<?xml version="1.0" encoding="utf-8"?>
<!-- This URDF was automatically created by SolidWorks to URDF Exporter! Originally created by Stephen Brawner (brawner@gmail.com) 
     Commit Version: 1.6.0-4-g7f85cfe  Build Version: 1.6.7995.38578
     For more information, please see http://wiki.ros.org/sw_urdf_exporter -->
<robot
  name="Assem1">
  <link
    name="base_link">
    <inertial>
      <origin
        xyz="-0.0040712 0.019218 -0.001832"
        rpy="0 0 0" />
      <mass
        value="0.79656" />
      <inertia
        ixx="0.0004247"
        ixy="-1.7557E-19"
        ixz="-1.3553E-19"
        iyy="0.006196"
        iyz="2.4885E-20"
        izz="0.0059702" />
    </inertial>
    <visual>
      <origin
        xyz="0 0 0"
        rpy="0 0 0" />
      <geometry>
        <mesh
          filename="package://Assem1/meshes/base_link.STL" />
      </geometry>
      <material
        name="">
        <color
          rgba="0.8 0.5 0 1" />
      </material>
    </visual>
    <collision>
      <origin
        xyz="0 0 0"
        rpy="0 0 0" />
      <geometry>
        <mesh
          filename="package://Assem1/meshes/base_link.STL" />
      </geometry>
    </collision>
  </link>
  <link
    name="link_left_forward">
    <inertial>
      <origin
        xyz="5.5511E-16 -5.8287E-16 0.015495"
        rpy="0 0 0" />
      <mass
        value="0.31743" />
      <inertia
        ixx="0.00029799"
        ixy="4.9476E-20"
        ixz="8.5125E-19"
        iyy="0.00029799"
        iyz="-7.8798E-19"
        izz="0.00053889" />
    </inertial>
    <visual>
      <origin
        xyz="0 0 0"
        rpy="0 0 0" />
      <geometry>
        <mesh
          filename="package://Assem1/meshes/link_left_forward.STL" />
      </geometry>
      <material
        name="">
        <color
          rgba="0.79216 0.81961 0.93333 1" />
      </material>
    </visual>
    <collision>
      <origin
        xyz="0 0 0"
        rpy="0 0 0" />
      <geometry>
        <mesh
          filename="package://Assem1/meshes/link_left_forward.STL" />
      </geometry>
    </collision>
  </link>
  <joint
    name="joint_left_forward"
    type="continuous">
    <origin
      xyz="0.12593 0.019896 -0.076832"
      rpy="0 0 0" />
    <parent
      link="base_link" />
    <child
      link="link_left_forward" />
    <axis
      xyz="0 0 1" />
  </joint>
  <link
    name="link_right_forward">
    <inertial>
      <origin
        xyz="-4.4409E-16 5.5511E-16 -0.015495"
        rpy="0 0 0" />
      <mass
        value="0.31743" />
      <inertia
        ixx="0.00029799"
        ixy="-4.5653E-20"
        ixz="1.5519E-20"
        iyy="0.00029799"
        iyz="-7.6746E-23"
        izz="0.00053889" />
    </inertial>
    <visual>
      <origin
        xyz="0 0 0"
        rpy="0 0 0" />
      <geometry>
        <mesh
          filename="package://Assem1/meshes/link_right_forward.STL" />
      </geometry>
      <material
        name="">
        <color
          rgba="0.79216 0.81961 0.93333 1" />
      </material>
    </visual>
    <collision>
      <origin
        xyz="0 0 0"
        rpy="0 0 0" />
      <geometry>
        <mesh
          filename="package://Assem1/meshes/link_right_forward.STL" />
      </geometry>
    </collision>
  </link>
  <joint
    name="joint_right_forward"
    type="continuous">
    <origin
      xyz="0.12593 0.019896 0.073168"
      rpy="0 0 0" />
    <parent
      link="base_link" />
    <child
      link="link_right_forward" />
    <axis
      xyz="0 0 1" />
  </joint>
  <link
    name="link_left_back">
    <inertial>
      <origin
        xyz="6.8955E-17 -2.7756E-17 0.015495"
        rpy="0 0 0" />
      <mass
        value="0.31743" />
      <inertia
        ixx="0.00029799"
        ixy="7.9409E-20"
        ixz="8.588E-19"
        iyy="0.00029799"
        iyz="-8.7157E-19"
        izz="0.00053889" />
    </inertial>
    <visual>
      <origin
        xyz="0 0 0"
        rpy="0 0 0" />
      <geometry>
        <mesh
          filename="package://Assem1/meshes/link_left_back.STL" />
      </geometry>
      <material
        name="">
        <color
          rgba="0.79216 0.81961 0.93333 1" />
      </material>
    </visual>
    <collision>
      <origin
        xyz="0 0 0"
        rpy="0 0 0" />
      <geometry>
        <mesh
          filename="package://Assem1/meshes/link_left_back.STL" />
      </geometry>
    </collision>
  </link>
  <joint
    name="joint_left_back"
    type="continuous">
    <origin
      xyz="-0.13407 0.019896 -0.076832"
      rpy="0 0 0" />
    <parent
      link="base_link" />
    <child
      link="link_left_back" />
    <axis
      xyz="0 0 1" />
  </joint>
  <link
    name="link_right_back">
    <inertial>
      <origin
        xyz="-0.003455 -0.00020356 -0.015495"
        rpy="0 0 0" />
      <mass
        value="0.31743" />
      <inertia
        ixx="0.00029799"
        ixy="-5.8657E-20"
        ixz="2.6807E-21"
        iyy="0.00029799"
        iyz="-7.14E-21"
        izz="0.00053889" />
    </inertial>
    <visual>
      <origin
        xyz="0 0 0"
        rpy="0 0 0" />
      <geometry>
        <mesh
          filename="package://Assem1/meshes/link_right_back.STL" />
      </geometry>
      <material
        name="">
        <color
          rgba="0.79216 0.81961 0.93333 1" />
      </material>
    </visual>
    <collision>
      <origin
        xyz="0 0 0"
        rpy="0 0 0" />
      <geometry>
        <mesh
          filename="package://Assem1/meshes/link_right_back.STL" />
      </geometry>
    </collision>
  </link>
  <joint
    name="joint_right_back"
    type="continuous">
    <origin
      xyz="-0.13062 0.020099 0.073168"
      rpy="0 0 0" />
    <parent
      link="base_link" />
    <child
      link="link_right_back" />
    <axis
      xyz="0 0 1" />
  </joint>
</robot>